2025-05-17 19:41:42 - ERROR - An error occurred: {str(e)}
2025-05-17 19:41:42 - ERROR - Traceback:
Traceback (most recent call last):
  File ".\ingestion.py", line 67, in sending_product_datas
    with open(r'D:\Projects\Python\224-CDCSDL-FinalProject\base\landing_zone\phone.json', 'r', encoding='utf-8') as jsonFile:
FileNotFoundError: [Errno 2] No such file or directory: 'D:\\Projects\\Python\\224-CDCSDL-FinalProject\\base\\landing_zone\\phone.json'
2025-05-17 19:44:35 - ERROR - An error occurred: {str(e)}
2025-05-17 19:44:35 - ERROR - Traceback:
Traceback (most recent call last):
  File ".\ingestion.py", line 67, in sending_product_datas
    with open(r'D:\Projects\Python\224-CDCSDL-FinalProject\base\landing_zone\phone.json', 'r', encoding='utf-8') as jsonFile:
FileNotFoundError: [Errno 2] No such file or directory: 'D:\\Projects\\Python\\224-CDCSDL-FinalProject\\base\\landing_zone\\phone.json'
2025-05-17 19:45:28 - INFO - [2025-05-17 19:45:28.604658] - Data being sent successfully
2025-05-17 19:45:55 - INFO - [2025-05-17 19:45:55.587210] - Data being sent successfully
2025-05-17 19:46:08 - INFO - [2025-05-17 19:46:08.124573] - Data being sent successfully
2025-05-17 19:46:08 - INFO - [2025-05-17 19:46:08.124573] - Data being sent successfully
2025-05-17 19:46:20 - INFO - [2025-05-17 19:46:20.168370] - Data being sent successfully
2025-05-17 19:46:21 - INFO - [2025-05-17 19:46:21.279721] - Data being sent successfully
2025-05-17 19:46:31 - INFO - [2025-05-17 19:46:31.160627] - Data being sent successfully
2025-05-17 19:46:32 - INFO - [2025-05-17 19:46:32.616115] - Data being sent successfully
2025-05-17 19:46:33 - INFO - [2025-05-17 19:46:33.539372] - Data being sent successfully
2025-05-17 19:46:34 - INFO - [2025-05-17 19:46:34.370711] - Data being sent successfully
2025-05-17 19:46:34 - INFO - [2025-05-17 19:46:34.983325] - Data being sent successfully
2025-05-17 19:46:35 - INFO - [2025-05-17 19:46:35.584387] - Data being sent successfully
2025-05-17 19:46:36 - INFO - [2025-05-17 19:46:36.195527] - Data being sent successfully
2025-05-17 19:46:36 - INFO - [2025-05-17 19:46:36.797041] - Data being sent successfully
2025-05-17 19:46:37 - INFO - [2025-05-17 19:46:37.436244] - Data being sent successfully
2025-05-17 19:46:38 - INFO - [2025-05-17 19:46:38.049800] - Data being sent successfully
2025-05-17 19:46:38 - INFO - [2025-05-17 19:46:38.650101] - Data being sent successfully
2025-05-17 19:47:10 - INFO - [2025-05-17 19:47:10.706075] - Data being sent successfully
2025-05-17 19:48:10 - INFO - [2025-05-17 19:48:10.090028] - Data being sent successfully
2025-05-17 19:48:11 - INFO - [2025-05-17 19:48:11.519795] - Data being sent successfully
2025-05-17 19:48:50 - INFO - [2025-05-17 19:48:50.680844] - Data being sent successfully
2025-05-17 19:49:05 - INFO - [2025-05-17 19:49:05.392774] - Data being sent successfully
2025-05-17 19:49:35 - INFO - [2025-05-17 19:49:35.966388] - Data being sent successfully
2025-05-17 19:49:37 - INFO - [2025-05-17 19:49:37.253229] - Data being sent successfully
2025-05-17 19:50:13 - INFO - [2025-05-17 19:50:13.062097] - Data being sent successfully
2025-05-17 19:50:14 - INFO - [2025-05-17 19:50:14.331469] - Data being sent successfully
2025-05-17 19:51:07 - INFO - [2025-05-17 19:51:07.986887] - Data being sent successfully
2025-05-17 19:52:49 - INFO - [2025-05-17 19:52:49.142400] - Data being sent successfully
2025-05-17 19:53:37 - INFO - [2025-05-17 19:53:37.238485] - Data being sent successfully
2025-05-17 20:14:28 - INFO - [2025-05-17 20:14:28.329601] - Data being sent successfully.
2025-05-17 20:16:15 - INFO - [2025-05-17 20:16:15.817173] - Data being sent successfully.
2025-05-17 20:21:13 - INFO - [2025-05-17 20:21:13.534643] - Data being sent successfully.
2025-05-17 20:21:18 - INFO - [2025-05-17 20:21:18.873106] - Data being sent successfully.
2025-05-17 20:21:24 - INFO - [2025-05-17 20:21:24.237815] - Data being sent successfully.
2025-05-17 20:21:29 - INFO - [2025-05-17 20:21:29.617481] - Data being sent successfully.
2025-05-17 20:21:34 - INFO - [2025-05-17 20:21:34.970784] - Data being sent successfully.
2025-05-17 20:21:40 - INFO - [2025-05-17 20:21:40.351428] - Data being sent successfully.
2025-05-17 20:21:45 - INFO - [2025-05-17 20:21:45.826540] - Data being sent successfully.
2025-05-17 20:21:51 - INFO - [2025-05-17 20:21:51.339574] - Data being sent successfully.
2025-05-17 20:21:56 - INFO - [2025-05-17 20:21:56.817172] - Data being sent successfully.
2025-05-17 20:22:02 - INFO - [2025-05-17 20:22:02.283547] - Data being sent successfully.
2025-05-17 20:22:07 - INFO - [2025-05-17 20:22:07.776339] - Data being sent successfully.
2025-05-17 20:22:13 - INFO - [2025-05-17 20:22:13.200048] - Data being sent successfully.
2025-05-17 20:22:20 - ERROR - An error occurred: {str(e)}
2025-05-17 20:22:20 - ERROR - Traceback:
Traceback (most recent call last):
  File "D:\Anaconda\envs\KDL\lib\site-packages\urllib3\connection.py", line 199, in _new_conn
    sock = connection.create_connection(
  File "D:\Anaconda\envs\KDL\lib\site-packages\urllib3\util\connection.py", line 85, in create_connection
    raise err
  File "D:\Anaconda\envs\KDL\lib\site-packages\urllib3\util\connection.py", line 73, in create_connection
    sock.connect(sa)
ConnectionRefusedError: [WinError 10061] No connection could be made because the target machine actively refused it

The above exception was the direct cause of the following exception:

Traceback (most recent call last):
  File "D:\Anaconda\envs\KDL\lib\site-packages\urllib3\connectionpool.py", line 789, in urlopen
    response = self._make_request(
  File "D:\Anaconda\envs\KDL\lib\site-packages\urllib3\connectionpool.py", line 495, in _make_request
    conn.request(
  File "D:\Anaconda\envs\KDL\lib\site-packages\urllib3\connection.py", line 441, in request
    self.endheaders()
  File "D:\Anaconda\envs\KDL\lib\http\client.py", line 1251, in endheaders
    self._send_output(message_body, encode_chunked=encode_chunked)
  File "D:\Anaconda\envs\KDL\lib\http\client.py", line 1011, in _send_output
    self.send(msg)
  File "D:\Anaconda\envs\KDL\lib\http\client.py", line 951, in send
    self.connect()
  File "D:\Anaconda\envs\KDL\lib\site-packages\urllib3\connection.py", line 279, in connect
    self.sock = self._new_conn()
  File "D:\Anaconda\envs\KDL\lib\site-packages\urllib3\connection.py", line 214, in _new_conn
    raise NewConnectionError(
urllib3.exceptions.NewConnectionError: <urllib3.connection.HTTPConnection object at 0x00000157E589D370>: Failed to establish a new connection: [WinError 10061] No connection could be made because the target machine actively refused it

The above exception was the direct cause of the following exception:

Traceback (most recent call last):
  File "D:\Anaconda\envs\KDL\lib\site-packages\requests\adapters.py", line 667, in send
    resp = conn.urlopen(
  File "D:\Anaconda\envs\KDL\lib\site-packages\urllib3\connectionpool.py", line 843, in urlopen
    retries = retries.increment(
  File "D:\Anaconda\envs\KDL\lib\site-packages\urllib3\util\retry.py", line 519, in increment
    raise MaxRetryError(_pool, url, reason) from reason  # type: ignore[arg-type]
urllib3.exceptions.MaxRetryError: HTTPConnectionPool(host='127.0.0.1', port=8000): Max retries exceeded with url: /insert-product/dtdd (Caused by NewConnectionError('<urllib3.connection.HTTPConnection object at 0x00000157E589D370>: Failed to establish a new connection: [WinError 10061] No connection could be made because the target machine actively refused it'))

During handling of the above exception, another exception occurred:

Traceback (most recent call last):
  File "D:\Projects\Python\224-CDCSDL-FinalProject\base\data_ingestion\.\app\ingestion.py", line 51, in sending_product_datas
    requests.post('http://127.0.0.1:8000/insert-product/dtdd', json=productDict[i])
  File "D:\Anaconda\envs\KDL\lib\site-packages\requests\api.py", line 115, in post
    return request("post", url, data=data, json=json, **kwargs)
  File "D:\Anaconda\envs\KDL\lib\site-packages\requests\api.py", line 59, in request
    return session.request(method=method, url=url, **kwargs)
  File "D:\Anaconda\envs\KDL\lib\site-packages\requests\sessions.py", line 589, in request
    resp = self.send(prep, **send_kwargs)
  File "D:\Anaconda\envs\KDL\lib\site-packages\requests\sessions.py", line 703, in send
    r = adapter.send(request, **kwargs)
  File "D:\Anaconda\envs\KDL\lib\site-packages\requests\adapters.py", line 700, in send
    raise ConnectionError(e, request=request)
requests.exceptions.ConnectionError: HTTPConnectionPool(host='127.0.0.1', port=8000): Max retries exceeded with url: /insert-product/dtdd (Caused by NewConnectionError('<urllib3.connection.HTTPConnection object at 0x00000157E589D370>: Failed to establish a new connection: [WinError 10061] No connection could be made because the target machine actively refused it'))
2025-05-17 20:22:27 - ERROR - An error occurred: {str(e)}
2025-05-17 20:22:27 - ERROR - Traceback:
Traceback (most recent call last):
  File "D:\Anaconda\envs\KDL\lib\site-packages\urllib3\connection.py", line 199, in _new_conn
    sock = connection.create_connection(
  File "D:\Anaconda\envs\KDL\lib\site-packages\urllib3\util\connection.py", line 85, in create_connection
    raise err
  File "D:\Anaconda\envs\KDL\lib\site-packages\urllib3\util\connection.py", line 73, in create_connection
    sock.connect(sa)
ConnectionRefusedError: [WinError 10061] No connection could be made because the target machine actively refused it

The above exception was the direct cause of the following exception:

Traceback (most recent call last):
  File "D:\Anaconda\envs\KDL\lib\site-packages\urllib3\connectionpool.py", line 789, in urlopen
    response = self._make_request(
  File "D:\Anaconda\envs\KDL\lib\site-packages\urllib3\connectionpool.py", line 495, in _make_request
    conn.request(
  File "D:\Anaconda\envs\KDL\lib\site-packages\urllib3\connection.py", line 441, in request
    self.endheaders()
  File "D:\Anaconda\envs\KDL\lib\http\client.py", line 1251, in endheaders
    self._send_output(message_body, encode_chunked=encode_chunked)
  File "D:\Anaconda\envs\KDL\lib\http\client.py", line 1011, in _send_output
    self.send(msg)
  File "D:\Anaconda\envs\KDL\lib\http\client.py", line 951, in send
    self.connect()
  File "D:\Anaconda\envs\KDL\lib\site-packages\urllib3\connection.py", line 279, in connect
    self.sock = self._new_conn()
  File "D:\Anaconda\envs\KDL\lib\site-packages\urllib3\connection.py", line 214, in _new_conn
    raise NewConnectionError(
urllib3.exceptions.NewConnectionError: <urllib3.connection.HTTPConnection object at 0x00000157E35B6160>: Failed to establish a new connection: [WinError 10061] No connection could be made because the target machine actively refused it

The above exception was the direct cause of the following exception:

Traceback (most recent call last):
  File "D:\Anaconda\envs\KDL\lib\site-packages\requests\adapters.py", line 667, in send
    resp = conn.urlopen(
  File "D:\Anaconda\envs\KDL\lib\site-packages\urllib3\connectionpool.py", line 843, in urlopen
    retries = retries.increment(
  File "D:\Anaconda\envs\KDL\lib\site-packages\urllib3\util\retry.py", line 519, in increment
    raise MaxRetryError(_pool, url, reason) from reason  # type: ignore[arg-type]
urllib3.exceptions.MaxRetryError: HTTPConnectionPool(host='127.0.0.1', port=8000): Max retries exceeded with url: /insert-product/dtdd (Caused by NewConnectionError('<urllib3.connection.HTTPConnection object at 0x00000157E35B6160>: Failed to establish a new connection: [WinError 10061] No connection could be made because the target machine actively refused it'))

During handling of the above exception, another exception occurred:

Traceback (most recent call last):
  File "D:\Projects\Python\224-CDCSDL-FinalProject\base\data_ingestion\.\app\ingestion.py", line 51, in sending_product_datas
    requests.post('http://127.0.0.1:8000/insert-product/dtdd', json=productDict[i])
  File "D:\Anaconda\envs\KDL\lib\site-packages\requests\api.py", line 115, in post
    return request("post", url, data=data, json=json, **kwargs)
  File "D:\Anaconda\envs\KDL\lib\site-packages\requests\api.py", line 59, in request
    return session.request(method=method, url=url, **kwargs)
  File "D:\Anaconda\envs\KDL\lib\site-packages\requests\sessions.py", line 589, in request
    resp = self.send(prep, **send_kwargs)
  File "D:\Anaconda\envs\KDL\lib\site-packages\requests\sessions.py", line 703, in send
    r = adapter.send(request, **kwargs)
  File "D:\Anaconda\envs\KDL\lib\site-packages\requests\adapters.py", line 700, in send
    raise ConnectionError(e, request=request)
requests.exceptions.ConnectionError: HTTPConnectionPool(host='127.0.0.1', port=8000): Max retries exceeded with url: /insert-product/dtdd (Caused by NewConnectionError('<urllib3.connection.HTTPConnection object at 0x00000157E35B6160>: Failed to establish a new connection: [WinError 10061] No connection could be made because the target machine actively refused it'))
2025-05-17 20:22:35 - ERROR - An error occurred: {str(e)}
2025-05-17 20:22:35 - ERROR - Traceback:
Traceback (most recent call last):
  File "D:\Anaconda\envs\KDL\lib\site-packages\urllib3\connection.py", line 199, in _new_conn
    sock = connection.create_connection(
  File "D:\Anaconda\envs\KDL\lib\site-packages\urllib3\util\connection.py", line 85, in create_connection
    raise err
  File "D:\Anaconda\envs\KDL\lib\site-packages\urllib3\util\connection.py", line 73, in create_connection
    sock.connect(sa)
ConnectionRefusedError: [WinError 10061] No connection could be made because the target machine actively refused it

The above exception was the direct cause of the following exception:

Traceback (most recent call last):
  File "D:\Anaconda\envs\KDL\lib\site-packages\urllib3\connectionpool.py", line 789, in urlopen
    response = self._make_request(
  File "D:\Anaconda\envs\KDL\lib\site-packages\urllib3\connectionpool.py", line 495, in _make_request
    conn.request(
  File "D:\Anaconda\envs\KDL\lib\site-packages\urllib3\connection.py", line 441, in request
    self.endheaders()
  File "D:\Anaconda\envs\KDL\lib\http\client.py", line 1251, in endheaders
    self._send_output(message_body, encode_chunked=encode_chunked)
  File "D:\Anaconda\envs\KDL\lib\http\client.py", line 1011, in _send_output
    self.send(msg)
  File "D:\Anaconda\envs\KDL\lib\http\client.py", line 951, in send
    self.connect()
  File "D:\Anaconda\envs\KDL\lib\site-packages\urllib3\connection.py", line 279, in connect
    self.sock = self._new_conn()
  File "D:\Anaconda\envs\KDL\lib\site-packages\urllib3\connection.py", line 214, in _new_conn
    raise NewConnectionError(
urllib3.exceptions.NewConnectionError: <urllib3.connection.HTTPConnection object at 0x00000157E589D370>: Failed to establish a new connection: [WinError 10061] No connection could be made because the target machine actively refused it

The above exception was the direct cause of the following exception:

Traceback (most recent call last):
  File "D:\Anaconda\envs\KDL\lib\site-packages\requests\adapters.py", line 667, in send
    resp = conn.urlopen(
  File "D:\Anaconda\envs\KDL\lib\site-packages\urllib3\connectionpool.py", line 843, in urlopen
    retries = retries.increment(
  File "D:\Anaconda\envs\KDL\lib\site-packages\urllib3\util\retry.py", line 519, in increment
    raise MaxRetryError(_pool, url, reason) from reason  # type: ignore[arg-type]
urllib3.exceptions.MaxRetryError: HTTPConnectionPool(host='127.0.0.1', port=8000): Max retries exceeded with url: /insert-product/dtdd (Caused by NewConnectionError('<urllib3.connection.HTTPConnection object at 0x00000157E589D370>: Failed to establish a new connection: [WinError 10061] No connection could be made because the target machine actively refused it'))

During handling of the above exception, another exception occurred:

Traceback (most recent call last):
  File "D:\Projects\Python\224-CDCSDL-FinalProject\base\data_ingestion\.\app\ingestion.py", line 51, in sending_product_datas
    requests.post('http://127.0.0.1:8000/insert-product/dtdd', json=productDict[i])
  File "D:\Anaconda\envs\KDL\lib\site-packages\requests\api.py", line 115, in post
    return request("post", url, data=data, json=json, **kwargs)
  File "D:\Anaconda\envs\KDL\lib\site-packages\requests\api.py", line 59, in request
    return session.request(method=method, url=url, **kwargs)
  File "D:\Anaconda\envs\KDL\lib\site-packages\requests\sessions.py", line 589, in request
    resp = self.send(prep, **send_kwargs)
  File "D:\Anaconda\envs\KDL\lib\site-packages\requests\sessions.py", line 703, in send
    r = adapter.send(request, **kwargs)
  File "D:\Anaconda\envs\KDL\lib\site-packages\requests\adapters.py", line 700, in send
    raise ConnectionError(e, request=request)
requests.exceptions.ConnectionError: HTTPConnectionPool(host='127.0.0.1', port=8000): Max retries exceeded with url: /insert-product/dtdd (Caused by NewConnectionError('<urllib3.connection.HTTPConnection object at 0x00000157E589D370>: Failed to establish a new connection: [WinError 10061] No connection could be made because the target machine actively refused it'))
2025-05-17 20:22:42 - ERROR - An error occurred: {str(e)}
2025-05-17 20:22:42 - ERROR - Traceback:
Traceback (most recent call last):
  File "D:\Anaconda\envs\KDL\lib\site-packages\urllib3\connection.py", line 199, in _new_conn
    sock = connection.create_connection(
  File "D:\Anaconda\envs\KDL\lib\site-packages\urllib3\util\connection.py", line 85, in create_connection
    raise err
  File "D:\Anaconda\envs\KDL\lib\site-packages\urllib3\util\connection.py", line 73, in create_connection
    sock.connect(sa)
ConnectionRefusedError: [WinError 10061] No connection could be made because the target machine actively refused it

The above exception was the direct cause of the following exception:

Traceback (most recent call last):
  File "D:\Anaconda\envs\KDL\lib\site-packages\urllib3\connectionpool.py", line 789, in urlopen
    response = self._make_request(
  File "D:\Anaconda\envs\KDL\lib\site-packages\urllib3\connectionpool.py", line 495, in _make_request
    conn.request(
  File "D:\Anaconda\envs\KDL\lib\site-packages\urllib3\connection.py", line 441, in request
    self.endheaders()
  File "D:\Anaconda\envs\KDL\lib\http\client.py", line 1251, in endheaders
    self._send_output(message_body, encode_chunked=encode_chunked)
  File "D:\Anaconda\envs\KDL\lib\http\client.py", line 1011, in _send_output
    self.send(msg)
  File "D:\Anaconda\envs\KDL\lib\http\client.py", line 951, in send
    self.connect()
  File "D:\Anaconda\envs\KDL\lib\site-packages\urllib3\connection.py", line 279, in connect
    self.sock = self._new_conn()
  File "D:\Anaconda\envs\KDL\lib\site-packages\urllib3\connection.py", line 214, in _new_conn
    raise NewConnectionError(
urllib3.exceptions.NewConnectionError: <urllib3.connection.HTTPConnection object at 0x00000157E593E220>: Failed to establish a new connection: [WinError 10061] No connection could be made because the target machine actively refused it

The above exception was the direct cause of the following exception:

Traceback (most recent call last):
  File "D:\Anaconda\envs\KDL\lib\site-packages\requests\adapters.py", line 667, in send
    resp = conn.urlopen(
  File "D:\Anaconda\envs\KDL\lib\site-packages\urllib3\connectionpool.py", line 843, in urlopen
    retries = retries.increment(
  File "D:\Anaconda\envs\KDL\lib\site-packages\urllib3\util\retry.py", line 519, in increment
    raise MaxRetryError(_pool, url, reason) from reason  # type: ignore[arg-type]
urllib3.exceptions.MaxRetryError: HTTPConnectionPool(host='127.0.0.1', port=8000): Max retries exceeded with url: /insert-product/dtdd (Caused by NewConnectionError('<urllib3.connection.HTTPConnection object at 0x00000157E593E220>: Failed to establish a new connection: [WinError 10061] No connection could be made because the target machine actively refused it'))

During handling of the above exception, another exception occurred:

Traceback (most recent call last):
  File "D:\Projects\Python\224-CDCSDL-FinalProject\base\data_ingestion\.\app\ingestion.py", line 51, in sending_product_datas
    requests.post('http://127.0.0.1:8000/insert-product/dtdd', json=productDict[i])
  File "D:\Anaconda\envs\KDL\lib\site-packages\requests\api.py", line 115, in post
    return request("post", url, data=data, json=json, **kwargs)
  File "D:\Anaconda\envs\KDL\lib\site-packages\requests\api.py", line 59, in request
    return session.request(method=method, url=url, **kwargs)
  File "D:\Anaconda\envs\KDL\lib\site-packages\requests\sessions.py", line 589, in request
    resp = self.send(prep, **send_kwargs)
  File "D:\Anaconda\envs\KDL\lib\site-packages\requests\sessions.py", line 703, in send
    r = adapter.send(request, **kwargs)
  File "D:\Anaconda\envs\KDL\lib\site-packages\requests\adapters.py", line 700, in send
    raise ConnectionError(e, request=request)
requests.exceptions.ConnectionError: HTTPConnectionPool(host='127.0.0.1', port=8000): Max retries exceeded with url: /insert-product/dtdd (Caused by NewConnectionError('<urllib3.connection.HTTPConnection object at 0x00000157E593E220>: Failed to establish a new connection: [WinError 10061] No connection could be made because the target machine actively refused it'))
2025-05-17 20:22:49 - ERROR - An error occurred: {str(e)}
2025-05-17 20:22:49 - ERROR - Traceback:
Traceback (most recent call last):
  File "D:\Anaconda\envs\KDL\lib\site-packages\urllib3\connection.py", line 199, in _new_conn
    sock = connection.create_connection(
  File "D:\Anaconda\envs\KDL\lib\site-packages\urllib3\util\connection.py", line 85, in create_connection
    raise err
  File "D:\Anaconda\envs\KDL\lib\site-packages\urllib3\util\connection.py", line 73, in create_connection
    sock.connect(sa)
ConnectionRefusedError: [WinError 10061] No connection could be made because the target machine actively refused it

The above exception was the direct cause of the following exception:

Traceback (most recent call last):
  File "D:\Anaconda\envs\KDL\lib\site-packages\urllib3\connectionpool.py", line 789, in urlopen
    response = self._make_request(
  File "D:\Anaconda\envs\KDL\lib\site-packages\urllib3\connectionpool.py", line 495, in _make_request
    conn.request(
  File "D:\Anaconda\envs\KDL\lib\site-packages\urllib3\connection.py", line 441, in request
    self.endheaders()
  File "D:\Anaconda\envs\KDL\lib\http\client.py", line 1251, in endheaders
    self._send_output(message_body, encode_chunked=encode_chunked)
  File "D:\Anaconda\envs\KDL\lib\http\client.py", line 1011, in _send_output
    self.send(msg)
  File "D:\Anaconda\envs\KDL\lib\http\client.py", line 951, in send
    self.connect()
  File "D:\Anaconda\envs\KDL\lib\site-packages\urllib3\connection.py", line 279, in connect
    self.sock = self._new_conn()
  File "D:\Anaconda\envs\KDL\lib\site-packages\urllib3\connection.py", line 214, in _new_conn
    raise NewConnectionError(
urllib3.exceptions.NewConnectionError: <urllib3.connection.HTTPConnection object at 0x00000157E593EBB0>: Failed to establish a new connection: [WinError 10061] No connection could be made because the target machine actively refused it

The above exception was the direct cause of the following exception:

Traceback (most recent call last):
  File "D:\Anaconda\envs\KDL\lib\site-packages\requests\adapters.py", line 667, in send
    resp = conn.urlopen(
  File "D:\Anaconda\envs\KDL\lib\site-packages\urllib3\connectionpool.py", line 843, in urlopen
    retries = retries.increment(
  File "D:\Anaconda\envs\KDL\lib\site-packages\urllib3\util\retry.py", line 519, in increment
    raise MaxRetryError(_pool, url, reason) from reason  # type: ignore[arg-type]
urllib3.exceptions.MaxRetryError: HTTPConnectionPool(host='127.0.0.1', port=8000): Max retries exceeded with url: /insert-product/dtdd (Caused by NewConnectionError('<urllib3.connection.HTTPConnection object at 0x00000157E593EBB0>: Failed to establish a new connection: [WinError 10061] No connection could be made because the target machine actively refused it'))

During handling of the above exception, another exception occurred:

Traceback (most recent call last):
  File "D:\Projects\Python\224-CDCSDL-FinalProject\base\data_ingestion\.\app\ingestion.py", line 51, in sending_product_datas
    requests.post('http://127.0.0.1:8000/insert-product/dtdd', json=productDict[i])
  File "D:\Anaconda\envs\KDL\lib\site-packages\requests\api.py", line 115, in post
    return request("post", url, data=data, json=json, **kwargs)
  File "D:\Anaconda\envs\KDL\lib\site-packages\requests\api.py", line 59, in request
    return session.request(method=method, url=url, **kwargs)
  File "D:\Anaconda\envs\KDL\lib\site-packages\requests\sessions.py", line 589, in request
    resp = self.send(prep, **send_kwargs)
  File "D:\Anaconda\envs\KDL\lib\site-packages\requests\sessions.py", line 703, in send
    r = adapter.send(request, **kwargs)
  File "D:\Anaconda\envs\KDL\lib\site-packages\requests\adapters.py", line 700, in send
    raise ConnectionError(e, request=request)
requests.exceptions.ConnectionError: HTTPConnectionPool(host='127.0.0.1', port=8000): Max retries exceeded with url: /insert-product/dtdd (Caused by NewConnectionError('<urllib3.connection.HTTPConnection object at 0x00000157E593EBB0>: Failed to establish a new connection: [WinError 10061] No connection could be made because the target machine actively refused it'))
2025-05-17 20:22:56 - ERROR - An error occurred: {str(e)}
2025-05-17 20:22:56 - ERROR - Traceback:
Traceback (most recent call last):
  File "D:\Anaconda\envs\KDL\lib\site-packages\urllib3\connection.py", line 199, in _new_conn
    sock = connection.create_connection(
  File "D:\Anaconda\envs\KDL\lib\site-packages\urllib3\util\connection.py", line 85, in create_connection
    raise err
  File "D:\Anaconda\envs\KDL\lib\site-packages\urllib3\util\connection.py", line 73, in create_connection
    sock.connect(sa)
ConnectionRefusedError: [WinError 10061] No connection could be made because the target machine actively refused it

The above exception was the direct cause of the following exception:

Traceback (most recent call last):
  File "D:\Anaconda\envs\KDL\lib\site-packages\urllib3\connectionpool.py", line 789, in urlopen
    response = self._make_request(
  File "D:\Anaconda\envs\KDL\lib\site-packages\urllib3\connectionpool.py", line 495, in _make_request
    conn.request(
  File "D:\Anaconda\envs\KDL\lib\site-packages\urllib3\connection.py", line 441, in request
    self.endheaders()
  File "D:\Anaconda\envs\KDL\lib\http\client.py", line 1251, in endheaders
    self._send_output(message_body, encode_chunked=encode_chunked)
  File "D:\Anaconda\envs\KDL\lib\http\client.py", line 1011, in _send_output
    self.send(msg)
  File "D:\Anaconda\envs\KDL\lib\http\client.py", line 951, in send
    self.connect()
  File "D:\Anaconda\envs\KDL\lib\site-packages\urllib3\connection.py", line 279, in connect
    self.sock = self._new_conn()
  File "D:\Anaconda\envs\KDL\lib\site-packages\urllib3\connection.py", line 214, in _new_conn
    raise NewConnectionError(
urllib3.exceptions.NewConnectionError: <urllib3.connection.HTTPConnection object at 0x00000157E589D580>: Failed to establish a new connection: [WinError 10061] No connection could be made because the target machine actively refused it

The above exception was the direct cause of the following exception:

Traceback (most recent call last):
  File "D:\Anaconda\envs\KDL\lib\site-packages\requests\adapters.py", line 667, in send
    resp = conn.urlopen(
  File "D:\Anaconda\envs\KDL\lib\site-packages\urllib3\connectionpool.py", line 843, in urlopen
    retries = retries.increment(
  File "D:\Anaconda\envs\KDL\lib\site-packages\urllib3\util\retry.py", line 519, in increment
    raise MaxRetryError(_pool, url, reason) from reason  # type: ignore[arg-type]
urllib3.exceptions.MaxRetryError: HTTPConnectionPool(host='127.0.0.1', port=8000): Max retries exceeded with url: /insert-product/dtdd (Caused by NewConnectionError('<urllib3.connection.HTTPConnection object at 0x00000157E589D580>: Failed to establish a new connection: [WinError 10061] No connection could be made because the target machine actively refused it'))

During handling of the above exception, another exception occurred:

Traceback (most recent call last):
  File "D:\Projects\Python\224-CDCSDL-FinalProject\base\data_ingestion\.\app\ingestion.py", line 51, in sending_product_datas
    requests.post('http://127.0.0.1:8000/insert-product/dtdd', json=productDict[i])
  File "D:\Anaconda\envs\KDL\lib\site-packages\requests\api.py", line 115, in post
    return request("post", url, data=data, json=json, **kwargs)
  File "D:\Anaconda\envs\KDL\lib\site-packages\requests\api.py", line 59, in request
    return session.request(method=method, url=url, **kwargs)
  File "D:\Anaconda\envs\KDL\lib\site-packages\requests\sessions.py", line 589, in request
    resp = self.send(prep, **send_kwargs)
  File "D:\Anaconda\envs\KDL\lib\site-packages\requests\sessions.py", line 703, in send
    r = adapter.send(request, **kwargs)
  File "D:\Anaconda\envs\KDL\lib\site-packages\requests\adapters.py", line 700, in send
    raise ConnectionError(e, request=request)
requests.exceptions.ConnectionError: HTTPConnectionPool(host='127.0.0.1', port=8000): Max retries exceeded with url: /insert-product/dtdd (Caused by NewConnectionError('<urllib3.connection.HTTPConnection object at 0x00000157E589D580>: Failed to establish a new connection: [WinError 10061] No connection could be made because the target machine actively refused it'))
2025-05-17 20:23:04 - ERROR - An error occurred: {str(e)}
2025-05-17 20:23:04 - ERROR - Traceback:
Traceback (most recent call last):
  File "D:\Anaconda\envs\KDL\lib\site-packages\urllib3\connection.py", line 199, in _new_conn
    sock = connection.create_connection(
  File "D:\Anaconda\envs\KDL\lib\site-packages\urllib3\util\connection.py", line 85, in create_connection
    raise err
  File "D:\Anaconda\envs\KDL\lib\site-packages\urllib3\util\connection.py", line 73, in create_connection
    sock.connect(sa)
ConnectionRefusedError: [WinError 10061] No connection could be made because the target machine actively refused it

The above exception was the direct cause of the following exception:

Traceback (most recent call last):
  File "D:\Anaconda\envs\KDL\lib\site-packages\urllib3\connectionpool.py", line 789, in urlopen
    response = self._make_request(
  File "D:\Anaconda\envs\KDL\lib\site-packages\urllib3\connectionpool.py", line 495, in _make_request
    conn.request(
  File "D:\Anaconda\envs\KDL\lib\site-packages\urllib3\connection.py", line 441, in request
    self.endheaders()
  File "D:\Anaconda\envs\KDL\lib\http\client.py", line 1251, in endheaders
    self._send_output(message_body, encode_chunked=encode_chunked)
  File "D:\Anaconda\envs\KDL\lib\http\client.py", line 1011, in _send_output
    self.send(msg)
  File "D:\Anaconda\envs\KDL\lib\http\client.py", line 951, in send
    self.connect()
  File "D:\Anaconda\envs\KDL\lib\site-packages\urllib3\connection.py", line 279, in connect
    self.sock = self._new_conn()
  File "D:\Anaconda\envs\KDL\lib\site-packages\urllib3\connection.py", line 214, in _new_conn
    raise NewConnectionError(
urllib3.exceptions.NewConnectionError: <urllib3.connection.HTTPConnection object at 0x00000157E35B62E0>: Failed to establish a new connection: [WinError 10061] No connection could be made because the target machine actively refused it

The above exception was the direct cause of the following exception:

Traceback (most recent call last):
  File "D:\Anaconda\envs\KDL\lib\site-packages\requests\adapters.py", line 667, in send
    resp = conn.urlopen(
  File "D:\Anaconda\envs\KDL\lib\site-packages\urllib3\connectionpool.py", line 843, in urlopen
    retries = retries.increment(
  File "D:\Anaconda\envs\KDL\lib\site-packages\urllib3\util\retry.py", line 519, in increment
    raise MaxRetryError(_pool, url, reason) from reason  # type: ignore[arg-type]
urllib3.exceptions.MaxRetryError: HTTPConnectionPool(host='127.0.0.1', port=8000): Max retries exceeded with url: /insert-product/dtdd (Caused by NewConnectionError('<urllib3.connection.HTTPConnection object at 0x00000157E35B62E0>: Failed to establish a new connection: [WinError 10061] No connection could be made because the target machine actively refused it'))

During handling of the above exception, another exception occurred:

Traceback (most recent call last):
  File "D:\Projects\Python\224-CDCSDL-FinalProject\base\data_ingestion\.\app\ingestion.py", line 51, in sending_product_datas
    requests.post('http://127.0.0.1:8000/insert-product/dtdd', json=productDict[i])
  File "D:\Anaconda\envs\KDL\lib\site-packages\requests\api.py", line 115, in post
    return request("post", url, data=data, json=json, **kwargs)
  File "D:\Anaconda\envs\KDL\lib\site-packages\requests\api.py", line 59, in request
    return session.request(method=method, url=url, **kwargs)
  File "D:\Anaconda\envs\KDL\lib\site-packages\requests\sessions.py", line 589, in request
    resp = self.send(prep, **send_kwargs)
  File "D:\Anaconda\envs\KDL\lib\site-packages\requests\sessions.py", line 703, in send
    r = adapter.send(request, **kwargs)
  File "D:\Anaconda\envs\KDL\lib\site-packages\requests\adapters.py", line 700, in send
    raise ConnectionError(e, request=request)
requests.exceptions.ConnectionError: HTTPConnectionPool(host='127.0.0.1', port=8000): Max retries exceeded with url: /insert-product/dtdd (Caused by NewConnectionError('<urllib3.connection.HTTPConnection object at 0x00000157E35B62E0>: Failed to establish a new connection: [WinError 10061] No connection could be made because the target machine actively refused it'))
2025-05-17 20:23:11 - ERROR - An error occurred: {str(e)}
2025-05-17 20:23:11 - ERROR - Traceback:
Traceback (most recent call last):
  File "D:\Anaconda\envs\KDL\lib\site-packages\urllib3\connection.py", line 199, in _new_conn
    sock = connection.create_connection(
  File "D:\Anaconda\envs\KDL\lib\site-packages\urllib3\util\connection.py", line 85, in create_connection
    raise err
  File "D:\Anaconda\envs\KDL\lib\site-packages\urllib3\util\connection.py", line 73, in create_connection
    sock.connect(sa)
ConnectionRefusedError: [WinError 10061] No connection could be made because the target machine actively refused it

The above exception was the direct cause of the following exception:

Traceback (most recent call last):
  File "D:\Anaconda\envs\KDL\lib\site-packages\urllib3\connectionpool.py", line 789, in urlopen
    response = self._make_request(
  File "D:\Anaconda\envs\KDL\lib\site-packages\urllib3\connectionpool.py", line 495, in _make_request
    conn.request(
  File "D:\Anaconda\envs\KDL\lib\site-packages\urllib3\connection.py", line 441, in request
    self.endheaders()
  File "D:\Anaconda\envs\KDL\lib\http\client.py", line 1251, in endheaders
    self._send_output(message_body, encode_chunked=encode_chunked)
  File "D:\Anaconda\envs\KDL\lib\http\client.py", line 1011, in _send_output
    self.send(msg)
  File "D:\Anaconda\envs\KDL\lib\http\client.py", line 951, in send
    self.connect()
  File "D:\Anaconda\envs\KDL\lib\site-packages\urllib3\connection.py", line 279, in connect
    self.sock = self._new_conn()
  File "D:\Anaconda\envs\KDL\lib\site-packages\urllib3\connection.py", line 214, in _new_conn
    raise NewConnectionError(
urllib3.exceptions.NewConnectionError: <urllib3.connection.HTTPConnection object at 0x00000157E593E190>: Failed to establish a new connection: [WinError 10061] No connection could be made because the target machine actively refused it

The above exception was the direct cause of the following exception:

Traceback (most recent call last):
  File "D:\Anaconda\envs\KDL\lib\site-packages\requests\adapters.py", line 667, in send
    resp = conn.urlopen(
  File "D:\Anaconda\envs\KDL\lib\site-packages\urllib3\connectionpool.py", line 843, in urlopen
    retries = retries.increment(
  File "D:\Anaconda\envs\KDL\lib\site-packages\urllib3\util\retry.py", line 519, in increment
    raise MaxRetryError(_pool, url, reason) from reason  # type: ignore[arg-type]
urllib3.exceptions.MaxRetryError: HTTPConnectionPool(host='127.0.0.1', port=8000): Max retries exceeded with url: /insert-product/dtdd (Caused by NewConnectionError('<urllib3.connection.HTTPConnection object at 0x00000157E593E190>: Failed to establish a new connection: [WinError 10061] No connection could be made because the target machine actively refused it'))

During handling of the above exception, another exception occurred:

Traceback (most recent call last):
  File "D:\Projects\Python\224-CDCSDL-FinalProject\base\data_ingestion\.\app\ingestion.py", line 51, in sending_product_datas
    requests.post('http://127.0.0.1:8000/insert-product/dtdd', json=productDict[i])
  File "D:\Anaconda\envs\KDL\lib\site-packages\requests\api.py", line 115, in post
    return request("post", url, data=data, json=json, **kwargs)
  File "D:\Anaconda\envs\KDL\lib\site-packages\requests\api.py", line 59, in request
    return session.request(method=method, url=url, **kwargs)
  File "D:\Anaconda\envs\KDL\lib\site-packages\requests\sessions.py", line 589, in request
    resp = self.send(prep, **send_kwargs)
  File "D:\Anaconda\envs\KDL\lib\site-packages\requests\sessions.py", line 703, in send
    r = adapter.send(request, **kwargs)
  File "D:\Anaconda\envs\KDL\lib\site-packages\requests\adapters.py", line 700, in send
    raise ConnectionError(e, request=request)
requests.exceptions.ConnectionError: HTTPConnectionPool(host='127.0.0.1', port=8000): Max retries exceeded with url: /insert-product/dtdd (Caused by NewConnectionError('<urllib3.connection.HTTPConnection object at 0x00000157E593E190>: Failed to establish a new connection: [WinError 10061] No connection could be made because the target machine actively refused it'))
2025-05-17 20:23:18 - ERROR - An error occurred: {str(e)}
2025-05-17 20:23:18 - ERROR - Traceback:
Traceback (most recent call last):
  File "D:\Anaconda\envs\KDL\lib\site-packages\urllib3\connection.py", line 199, in _new_conn
    sock = connection.create_connection(
  File "D:\Anaconda\envs\KDL\lib\site-packages\urllib3\util\connection.py", line 85, in create_connection
    raise err
  File "D:\Anaconda\envs\KDL\lib\site-packages\urllib3\util\connection.py", line 73, in create_connection
    sock.connect(sa)
ConnectionRefusedError: [WinError 10061] No connection could be made because the target machine actively refused it

The above exception was the direct cause of the following exception:

Traceback (most recent call last):
  File "D:\Anaconda\envs\KDL\lib\site-packages\urllib3\connectionpool.py", line 789, in urlopen
    response = self._make_request(
  File "D:\Anaconda\envs\KDL\lib\site-packages\urllib3\connectionpool.py", line 495, in _make_request
    conn.request(
  File "D:\Anaconda\envs\KDL\lib\site-packages\urllib3\connection.py", line 441, in request
    self.endheaders()
  File "D:\Anaconda\envs\KDL\lib\http\client.py", line 1251, in endheaders
    self._send_output(message_body, encode_chunked=encode_chunked)
  File "D:\Anaconda\envs\KDL\lib\http\client.py", line 1011, in _send_output
    self.send(msg)
  File "D:\Anaconda\envs\KDL\lib\http\client.py", line 951, in send
    self.connect()
  File "D:\Anaconda\envs\KDL\lib\site-packages\urllib3\connection.py", line 279, in connect
    self.sock = self._new_conn()
  File "D:\Anaconda\envs\KDL\lib\site-packages\urllib3\connection.py", line 214, in _new_conn
    raise NewConnectionError(
urllib3.exceptions.NewConnectionError: <urllib3.connection.HTTPConnection object at 0x00000157E593E2B0>: Failed to establish a new connection: [WinError 10061] No connection could be made because the target machine actively refused it

The above exception was the direct cause of the following exception:

Traceback (most recent call last):
  File "D:\Anaconda\envs\KDL\lib\site-packages\requests\adapters.py", line 667, in send
    resp = conn.urlopen(
  File "D:\Anaconda\envs\KDL\lib\site-packages\urllib3\connectionpool.py", line 843, in urlopen
    retries = retries.increment(
  File "D:\Anaconda\envs\KDL\lib\site-packages\urllib3\util\retry.py", line 519, in increment
    raise MaxRetryError(_pool, url, reason) from reason  # type: ignore[arg-type]
urllib3.exceptions.MaxRetryError: HTTPConnectionPool(host='127.0.0.1', port=8000): Max retries exceeded with url: /insert-product/dtdd (Caused by NewConnectionError('<urllib3.connection.HTTPConnection object at 0x00000157E593E2B0>: Failed to establish a new connection: [WinError 10061] No connection could be made because the target machine actively refused it'))

During handling of the above exception, another exception occurred:

Traceback (most recent call last):
  File "D:\Projects\Python\224-CDCSDL-FinalProject\base\data_ingestion\.\app\ingestion.py", line 51, in sending_product_datas
    requests.post('http://127.0.0.1:8000/insert-product/dtdd', json=productDict[i])
  File "D:\Anaconda\envs\KDL\lib\site-packages\requests\api.py", line 115, in post
    return request("post", url, data=data, json=json, **kwargs)
  File "D:\Anaconda\envs\KDL\lib\site-packages\requests\api.py", line 59, in request
    return session.request(method=method, url=url, **kwargs)
  File "D:\Anaconda\envs\KDL\lib\site-packages\requests\sessions.py", line 589, in request
    resp = self.send(prep, **send_kwargs)
  File "D:\Anaconda\envs\KDL\lib\site-packages\requests\sessions.py", line 703, in send
    r = adapter.send(request, **kwargs)
  File "D:\Anaconda\envs\KDL\lib\site-packages\requests\adapters.py", line 700, in send
    raise ConnectionError(e, request=request)
requests.exceptions.ConnectionError: HTTPConnectionPool(host='127.0.0.1', port=8000): Max retries exceeded with url: /insert-product/dtdd (Caused by NewConnectionError('<urllib3.connection.HTTPConnection object at 0x00000157E593E2B0>: Failed to establish a new connection: [WinError 10061] No connection could be made because the target machine actively refused it'))
2025-05-17 20:23:26 - ERROR - An error occurred: {str(e)}
2025-05-17 20:23:26 - ERROR - Traceback:
Traceback (most recent call last):
  File "D:\Anaconda\envs\KDL\lib\site-packages\urllib3\connection.py", line 199, in _new_conn
    sock = connection.create_connection(
  File "D:\Anaconda\envs\KDL\lib\site-packages\urllib3\util\connection.py", line 85, in create_connection
    raise err
  File "D:\Anaconda\envs\KDL\lib\site-packages\urllib3\util\connection.py", line 73, in create_connection
    sock.connect(sa)
ConnectionRefusedError: [WinError 10061] No connection could be made because the target machine actively refused it

The above exception was the direct cause of the following exception:

Traceback (most recent call last):
  File "D:\Anaconda\envs\KDL\lib\site-packages\urllib3\connectionpool.py", line 789, in urlopen
    response = self._make_request(
  File "D:\Anaconda\envs\KDL\lib\site-packages\urllib3\connectionpool.py", line 495, in _make_request
    conn.request(
  File "D:\Anaconda\envs\KDL\lib\site-packages\urllib3\connection.py", line 441, in request
    self.endheaders()
  File "D:\Anaconda\envs\KDL\lib\http\client.py", line 1251, in endheaders
    self._send_output(message_body, encode_chunked=encode_chunked)
  File "D:\Anaconda\envs\KDL\lib\http\client.py", line 1011, in _send_output
    self.send(msg)
  File "D:\Anaconda\envs\KDL\lib\http\client.py", line 951, in send
    self.connect()
  File "D:\Anaconda\envs\KDL\lib\site-packages\urllib3\connection.py", line 279, in connect
    self.sock = self._new_conn()
  File "D:\Anaconda\envs\KDL\lib\site-packages\urllib3\connection.py", line 214, in _new_conn
    raise NewConnectionError(
urllib3.exceptions.NewConnectionError: <urllib3.connection.HTTPConnection object at 0x00000157E589D1C0>: Failed to establish a new connection: [WinError 10061] No connection could be made because the target machine actively refused it

The above exception was the direct cause of the following exception:

Traceback (most recent call last):
  File "D:\Anaconda\envs\KDL\lib\site-packages\requests\adapters.py", line 667, in send
    resp = conn.urlopen(
  File "D:\Anaconda\envs\KDL\lib\site-packages\urllib3\connectionpool.py", line 843, in urlopen
    retries = retries.increment(
  File "D:\Anaconda\envs\KDL\lib\site-packages\urllib3\util\retry.py", line 519, in increment
    raise MaxRetryError(_pool, url, reason) from reason  # type: ignore[arg-type]
urllib3.exceptions.MaxRetryError: HTTPConnectionPool(host='127.0.0.1', port=8000): Max retries exceeded with url: /insert-product/dtdd (Caused by NewConnectionError('<urllib3.connection.HTTPConnection object at 0x00000157E589D1C0>: Failed to establish a new connection: [WinError 10061] No connection could be made because the target machine actively refused it'))

During handling of the above exception, another exception occurred:

Traceback (most recent call last):
  File "D:\Projects\Python\224-CDCSDL-FinalProject\base\data_ingestion\.\app\ingestion.py", line 51, in sending_product_datas
    requests.post('http://127.0.0.1:8000/insert-product/dtdd', json=productDict[i])
  File "D:\Anaconda\envs\KDL\lib\site-packages\requests\api.py", line 115, in post
    return request("post", url, data=data, json=json, **kwargs)
  File "D:\Anaconda\envs\KDL\lib\site-packages\requests\api.py", line 59, in request
    return session.request(method=method, url=url, **kwargs)
  File "D:\Anaconda\envs\KDL\lib\site-packages\requests\sessions.py", line 589, in request
    resp = self.send(prep, **send_kwargs)
  File "D:\Anaconda\envs\KDL\lib\site-packages\requests\sessions.py", line 703, in send
    r = adapter.send(request, **kwargs)
  File "D:\Anaconda\envs\KDL\lib\site-packages\requests\adapters.py", line 700, in send
    raise ConnectionError(e, request=request)
requests.exceptions.ConnectionError: HTTPConnectionPool(host='127.0.0.1', port=8000): Max retries exceeded with url: /insert-product/dtdd (Caused by NewConnectionError('<urllib3.connection.HTTPConnection object at 0x00000157E589D1C0>: Failed to establish a new connection: [WinError 10061] No connection could be made because the target machine actively refused it'))
2025-05-17 20:23:33 - ERROR - An error occurred: {str(e)}
2025-05-17 20:23:33 - ERROR - Traceback:
Traceback (most recent call last):
  File "D:\Anaconda\envs\KDL\lib\site-packages\urllib3\connection.py", line 199, in _new_conn
    sock = connection.create_connection(
  File "D:\Anaconda\envs\KDL\lib\site-packages\urllib3\util\connection.py", line 85, in create_connection
    raise err
  File "D:\Anaconda\envs\KDL\lib\site-packages\urllib3\util\connection.py", line 73, in create_connection
    sock.connect(sa)
ConnectionRefusedError: [WinError 10061] No connection could be made because the target machine actively refused it

The above exception was the direct cause of the following exception:

Traceback (most recent call last):
  File "D:\Anaconda\envs\KDL\lib\site-packages\urllib3\connectionpool.py", line 789, in urlopen
    response = self._make_request(
  File "D:\Anaconda\envs\KDL\lib\site-packages\urllib3\connectionpool.py", line 495, in _make_request
    conn.request(
  File "D:\Anaconda\envs\KDL\lib\site-packages\urllib3\connection.py", line 441, in request
    self.endheaders()
  File "D:\Anaconda\envs\KDL\lib\http\client.py", line 1251, in endheaders
    self._send_output(message_body, encode_chunked=encode_chunked)
  File "D:\Anaconda\envs\KDL\lib\http\client.py", line 1011, in _send_output
    self.send(msg)
  File "D:\Anaconda\envs\KDL\lib\http\client.py", line 951, in send
    self.connect()
  File "D:\Anaconda\envs\KDL\lib\site-packages\urllib3\connection.py", line 279, in connect
    self.sock = self._new_conn()
  File "D:\Anaconda\envs\KDL\lib\site-packages\urllib3\connection.py", line 214, in _new_conn
    raise NewConnectionError(
urllib3.exceptions.NewConnectionError: <urllib3.connection.HTTPConnection object at 0x00000157E583E640>: Failed to establish a new connection: [WinError 10061] No connection could be made because the target machine actively refused it

The above exception was the direct cause of the following exception:

Traceback (most recent call last):
  File "D:\Anaconda\envs\KDL\lib\site-packages\requests\adapters.py", line 667, in send
    resp = conn.urlopen(
  File "D:\Anaconda\envs\KDL\lib\site-packages\urllib3\connectionpool.py", line 843, in urlopen
    retries = retries.increment(
  File "D:\Anaconda\envs\KDL\lib\site-packages\urllib3\util\retry.py", line 519, in increment
    raise MaxRetryError(_pool, url, reason) from reason  # type: ignore[arg-type]
urllib3.exceptions.MaxRetryError: HTTPConnectionPool(host='127.0.0.1', port=8000): Max retries exceeded with url: /insert-product/dtdd (Caused by NewConnectionError('<urllib3.connection.HTTPConnection object at 0x00000157E583E640>: Failed to establish a new connection: [WinError 10061] No connection could be made because the target machine actively refused it'))

During handling of the above exception, another exception occurred:

Traceback (most recent call last):
  File "D:\Projects\Python\224-CDCSDL-FinalProject\base\data_ingestion\.\app\ingestion.py", line 51, in sending_product_datas
    requests.post('http://127.0.0.1:8000/insert-product/dtdd', json=productDict[i])
  File "D:\Anaconda\envs\KDL\lib\site-packages\requests\api.py", line 115, in post
    return request("post", url, data=data, json=json, **kwargs)
  File "D:\Anaconda\envs\KDL\lib\site-packages\requests\api.py", line 59, in request
    return session.request(method=method, url=url, **kwargs)
  File "D:\Anaconda\envs\KDL\lib\site-packages\requests\sessions.py", line 589, in request
    resp = self.send(prep, **send_kwargs)
  File "D:\Anaconda\envs\KDL\lib\site-packages\requests\sessions.py", line 703, in send
    r = adapter.send(request, **kwargs)
  File "D:\Anaconda\envs\KDL\lib\site-packages\requests\adapters.py", line 700, in send
    raise ConnectionError(e, request=request)
requests.exceptions.ConnectionError: HTTPConnectionPool(host='127.0.0.1', port=8000): Max retries exceeded with url: /insert-product/dtdd (Caused by NewConnectionError('<urllib3.connection.HTTPConnection object at 0x00000157E583E640>: Failed to establish a new connection: [WinError 10061] No connection could be made because the target machine actively refused it'))
